Workbook

Sheet Datos Generales
A1: PLANTILLA PARA CALIBRACIÓN DE MULTÍMETROS DIGITALES
A2: Cálculo de Incertidumbres según GUM / EA-4/02 / INM Colombia / CEM España
A4: DATOS DEL CERTIFICADO
A5: N° Certificado: | C5: Fecha de Calibración:
A6: Laboratorio: | B6: Laboratorio Delta | C6: Responsable: | D6: Bryan Suazo/ Felipe Cespedes
A8: DATOS DEL INSTRUMENTO BAJO CALIBRACIÓN (IBC)
A9: Marca: | B9: Arduino | C9: Modelo: | D9: INA219
A10: N° Serie: | C10: Código Interno:
A11: Resolución (dígitos): | C11: Tipo:
A12: Propietario: | C12: Ubicación:
A14: DATOS DEL PATRÓN (CALIBRADOR MULTIFUNCIÓN)
A15: Marca: | C15: Modelo:
A16: N° Serie: | C16: N° Certificado:
A17: Fecha Certificado: | C17: Próxima Calibración:
A18: Laboratorio que Calibró:
A20: CONDICIONES AMBIENTALES
A21: Temperatura (°C): | C21: Humedad Relativa (%):
A22: Rango Temp. Permitido: | B22: 18 - 28 | C22: Rango HR Permitido: | D22: ≤ 70
A24: INSTRUCCIONES DE USO
A25: 1. Complete los datos generales en esta hoja (celdas amarillas).
A26: 2. Vaya a cada hoja de magnitud según necesite calibrar:
A27: • Tensión DC, Tensión AC, Corriente DC, Corriente AC
A28: • Resistencia, Capacitancia, Frecuencia
A29: 3. Ingrese los valores del patrón y las 5 lecturas del IBC en las celdas amarillas.
A30: 4. Las incertidumbres se calcularán automáticamente.
A31: 5. Use la hoja 'Welch-Satterthwaite' para calcular el factor k exacto si tiene pocos grados de libertad.
A32: 6. Consulte la hoja 'Resumen Certificado' para el informe final.
A34: NOTA SOBRE WELCH-SATTERTHWAITE
A35: La hoja 'Welch-Satterthwaite' permite calcular los grados efectivos de libertad (νeff)
A36: para determinar el factor de cobertura k correcto según la distribución t de Student.
... A38: o cuando una componente de incertidumbre domina sobre las demás.

Sheet Tensión DC
A1: CALIBRACIÓN EN TENSIÓN CONTINUA (DC)
A3: PARÁMETROS DEL PATRÓN
A4: Especificación del fabricante (ppm de lectura): | C4: 22
A5: Especificación del fabricante (µV offset): | C5: 39
A6: Incertidumbre certificado patrón U (del certificado): | C6: 3.3e-05 | D6: V
A7: Factor de cobertura k del certificado: | C7: 2
A9: TABLA DE MEDICIONES Y CÁLCULO DE INCERTIDUMBRES INA 3
A10: Rango | B10: Valor Patrón | C10: Unidad | D10: Lect. 1 | E10: Lect. 2 | F10: Lect. 3 | G10: Lect. 4 | H10: Lect. 5 | I10: Promedio | J10: Resolución | K10: Error (E) | L10: u(rep) | M10: u(res) | N10: u(cert) | O10: u(espec) | P10: u_c | Q10: k | R10: U
B11: (Vs) | D11: (Vx1) | E11: (Vx2) | F11: (Vx3) | G11: (Vx4) | H11: (Vx5) | I11: (V̄x) | J11: (dig) | K11: (V̄x - Vs) | L11: Tipo A | M11: Tipo B | N11: Tipo B | O11: Tipo B | P11: Comb. | R11: Expand.
A12: 2.8 | B12: 2.882 | C12: V | D12: 2.852 | E12: 2.853 | F12: 2.852 | G12: 2.852 | H12: 2.852 | I12: =IF(COUNT(D12:H12)>0,AVERAGE(D12:H12),"") -> 2.8522 | J12: 0.001 | K12: =IF(I12<>"",I12-B12,"") -> -0.0298 | L12: =IF(COUNT(D12:H12)>1,STDEV(D12:H12)/SQRT(COUNT(D12:H12)),0) -> 0.0002 | M12: =IF(J12<>"",J12/(2*SQRT(3)),0) -> 0.00028867513 | N12: =IF($C$6<>"",$C$6/$C$7,0) -> 1.65e-05 | O12: =IF(B12<>"",($C$4*0.000001*ABS(B12)+$C$5*0.000001)/SQRT(3),0) -> 5.9122977e-05 | P12: =IF(I12<>"",SQRT(L12^2+M12^2+N12^2+O12^2),"") -> 0.00035651243 | Q12: =IF(P12<>"",2,"") -> 2 | R12: =IF(P12<>"",Q12*P12,"") -> 0.00071302485
A13: 3.3 | B13: 3.32 | C13: V | D13: 3.358 | E13: 3.358 | F13: 3.357 | G13: 3.357 | H13: 3.358 | I13: =IF(COUNT(D13:H13)>0,AVERAGE(D13:H13),"") -> 3.3576 | J13: 0.001 | K13: =IF(I13<>"",I13-B13,"") -> 0.0376 | L13: =IF(COUNT(D13:H13)>1,STDEV(D13:H13)/SQRT(COUNT(D13:H13)),0) -> 0.00024494897 | M13: =IF(J13<>"",J13/(2*SQRT(3)),0) -> 0.00028867513 | N13: =IF($C$6<>"",$C$6/$C$7,0) -> 1.65e-05 | O13: =IF(B13<>"",($C$4*0.000001*ABS(B13)+$C$5*0.000001)/SQRT(3),0) -> 6.4686324e-05 | P13: =IF(I13<>"",SQRT(L13^2+M13^2+N13^2+O13^2),"") -> 0.00038443452 | Q13: =IF(P13<>"",2,"") -> 2 | R13: =IF(P13<>"",Q13*P13,"") -> 0.00076886905
A14: 3.7 | B14: 3.718 | C14: V | D14: 3.761 | E14: 3.762 | F14: 3.762 | G14: 3.761 | H14: 3.761 | I14: =IF(COUNT(D14:H14)>0,AVERAGE(D14:H14),"") -> 3.7614 | J14: 0.01 | K14: =IF(I14<>"",I14-B14,"") -> 0.0434 | L14: =IF(COUNT(D14:H14)>1,STDEV(D14:H14)/SQRT(COUNT(D14:H14)),0) -> 0.00024494897 | M14: =IF(J14<>"",J14/(2*SQRT(3)),0) -> 0.0028867513 | N14: =IF($C$6<>"",$C$6/$C$7,0) -> 1.65e-05 | O14: =IF(B14<>"",($C$4*0.000001*ABS(B14)+$C$5*0.000001)/SQRT(3),0) -> 6.9741603e-05 | P14: =IF(I14<>"",SQRT(L14^2+M14^2+N14^2+O14^2),"") -> 0.0028980113 | Q14: =IF(P14<>"",2,"") -> 2 | R14: =IF(P14<>"",Q14*P14,"") -> 0.0057960226
A15: 4.2 | B15: 4.216 | C15: V | D15: 4.267 | E15: 4.266 | F15: 4.267 | G15: 4.267 | H15: 4.267 | I15: =IF(COUNT(D15:H15)>0,AVERAGE(D15:H15),"") -> 4.2668 | J15: 0.1 | K15: =IF(I15<>"",I15-B15,"") -> 0.0508 | L15: =IF(COUNT(D15:H15)>1,STDEV(D15:H15)/SQRT(COUNT(D15:H15)),0) -> 0.0002 | M15: =IF(J15<>"",J15/(2*SQRT(3)),0) -> 0.028867513 | N15: =IF($C$6<>"",$C$6/$C$7,0) -> 1.65e-05 | O15: =IF(B15<>"",($C$4*0.000001*ABS(B15)+$C$5*0.000001)/SQRT(3),0) -> 7.6067053e-05 | P15: =IF(I15<>"",SQRT(L15^2+M15^2+N15^2+O15^2),"") -> 0.028868311 | Q15: =IF(P15<>"",2,"") -> 2 | R15: =IF(P15<>"",Q15*P15,"") -> 0.057736622
A16: 5 | B16: 5.005 | C16: V | D16: 5.066 | E16: 5.066 | F16: 5.066 | G16: 5.068 | H16: 5.067 | I16: =IF(COUNT(D16:H16)>0,AVERAGE(D16:H16),"") -> 5.0666 | J16: 1 | K16: =IF(I16<>"",I16-B16,"") -> 0.0616 | L16: =IF(COUNT(D16:H16)>1,STDEV(D16:H16)/SQRT(COUNT(D16:H16)),0) -> 0.0004 | M16: =IF(J16<>"",J16/(2*SQRT(3)),0) -> 0.28867513 | N16: =IF($C$6<>"",$C$6/$C$7,0) -> 1.65e-05 | O16: =IF(B16<>"",($C$4*0.000001*ABS(B16)+$C$5*0.000001)/SQRT(3),0) -> 8.6088699e-05 | P16: =IF(I16<>"",SQRT(L16^2+M16^2+N16^2+O16^2),"") -> 0.28867543 | Q16: =IF(P16<>"",2,"") -> 2 | R16: =IF(P16<>"",Q16*P16,"") -> 0.57735085
I17: =IF(COUNT(D17:H17)>0,AVERAGE(D17:H17),"") | K17: =IF(I17<>"",I17-B17,"") | L17: =IF(COUNT(D17:H17)>1,STDEV(D17:H17)/SQRT(COUNT(D17:H17)),0) -> 0 | M17: =IF(J17<>"",J17/(2*SQRT(3)),0) -> 0 | N17: =IF($C$6<>"",$C$6/$C$7,0) -> 1.65e-05 | O17: =IF(B17<>"",($C$4*0.000001*ABS(B17)+$C$5*0.000001)/SQRT(3),0) -> 0 | P17: =IF(I17<>"",SQRT(L17^2+M17^2+N17^2+O17^2),"") | Q17: =IF(P17<>"",2,"") | R17: =IF(P17<>"",Q17*P17,"")
I18: =IF(COUNT(D18:H18)>0,AVERAGE(D18:H18),"") | K18: =IF(I18<>"",I18-B18,"") | L18: =IF(COUNT(D18:H18)>1,STDEV(D18:H18)/SQRT(COUNT(D18:H18)),0) -> 0 | M18: =IF(J18<>"",J18/(2*SQRT(3)),0) -> 0 | N18: =IF($C$6<>"",$C$6/$C$7,0) -> 1.65e-05 | O18: =IF(B18<>"",($C$4*0.000001*ABS(B18)+$C$5*0.000001)/SQRT(3),0) -> 0 | P18: =IF(I18<>"",SQRT(L18^2+M18^2+N18^2+O18^2),"") | Q18: =IF(P18<>"",2,"") | R18: =IF(P18<>"",Q18*P18,"")
I19: =IF(COUNT(D19:H19)>0,AVERAGE(D19:H19),"") | K19: =IF(I19<>"",I19-B19,"") | L19: =IF(COUNT(D19:H19)>1,STDEV(D19:H19)/SQRT(COUNT(D19:H19)),0) -> 0 | M19: =IF(J19<>"",J19/(2*SQRT(3)),0) -> 0 | N19: =IF($C$6<>"",$C$6/$C$7,0) -> 1.65e-05 | O19: =IF(B19<>"",($C$4*0.000001*ABS(B19)+$C$5*0.000001)/SQRT(3),0) -> 0 | P19: =IF(I19<>"",SQRT(L19^2+M19^2+N19^2+O19^2),"") | Q19: =IF(P19<>"",2,"") | R19: =IF(P19<>"",Q19*P19,"")
I20: =IF(COUNT(D20:H20)>0,AVERAGE(D20:H20),"") | K20: =IF(I20<>"",I20-B20,"") | L20: =IF(COUNT(D20:H20)>1,STDEV(D20:H20)/SQRT(COUNT(D20:H20)),0) -> 0 | M20: =IF(J20<>"",J20/(2*SQRT(3)),0) -> 0 | N20: =IF($C$6<>"",$C$6/$C$7,0) -> 1.65e-05 | O20: =IF(B20<>"",($C$4*0.000001*ABS(B20)+$C$5*0.000001)/SQRT(3),0) -> 0 | P20: =IF(I20<>"",SQRT(L20^2+M20^2+N20^2+O20^2),"") | Q20: =IF(P20<>"",2,"") | R20: =IF(P20<>"",Q20*P20,"")
I21: =IF(COUNT(D21:H21)>0,AVERAGE(D21:H21),"") | K21: =IF(I21<>"",I21-B21,"") | L21: =IF(COUNT(D21:H21)>1,STDEV(D21:H21)/SQRT(COUNT(D21:H21)),0) -> 0 | M21: =IF(J21<>"",J21/(2*SQRT(3)),0) -> 0 | N21: =IF($C$6<>"",$C$6/$C$7,0) -> 1.65e-05 | O21: =IF(B21<>"",($C$4*0.000001*ABS(B21)+$C$5*0.000001)/SQRT(3),0) -> 0 | P21: =IF(I21<>"",SQRT(L21^2+M21^2+N21^2+O21^2),"") | Q21: =IF(P21<>"",2,"") | R21: =IF(P21<>"",Q21*P21,"")
A23: LEYENDA Y FÓRMULAS UTILIZADAS
A24: u(rep) - Incertidumbre por repetibilidad (Tipo A): | D24: u(V̄x) = s(Vx) / √n
A25: u(res) - Incertidumbre por resolución (Tipo B): | D25: u(δVx) = resolución / (2·√3)
A26: u(cert) - Incertidumbre del certificado del patrón: | D26: u(Vs) = U_certificado / k
A27: u(espec) - Incertidumbre por especificaciones del patrón: | D27: u(δVs) = (ppm·|Vs| + offset) / √3
A28: u_c - Incertidumbre combinada: | D28: uc = √(u_rep² + u_res² + u_cert² + u_espec²)
A29: U - Incertidumbre expandida: | D29: U = k · uc (k=2 para 95.45%)
A31: NOTA: Las celdas en amarillo son de entrada. Ingrese los valores del patrón, las 5 lecturas del IBC y la resolución.
A33: CÁLCULO AVANZADO DEL FACTOR k (OPCIONAL)
A34: Para un cálculo más preciso del factor k usando la fórmula de Welch-Satterthwaite:
A35: Grados de libertad para incertidumbres Tipo B (asumiendo 5% de inseguridad): | E35: 200
A36: Número de repeticiones (n): | E36: 5
A37: Grados de libertad Tipo A (n-1): | E37: =E36-1 -> 4
A39: Nota: Si una fuente de incertidumbre rectangular es dominante (> 50% de u_c²),
A40: usar k ≈ 1.65 para 95% de probabilidad de cobertura en lugar de k=2.

Sheet Tensión AC
A1: CALIBRACIÓN EN TENSIÓN ALTERNA (AC)
A3: PARÁMETROS DEL PATRÓN
A4: Especificación del fabricante (ppm de lectura): | C4: 40
A5: Especificación del fabricante (µV offset): | C5: 100
A6: Incertidumbre certificado patrón U: | C6: 0.00012 | D6: V
A7: Factor de cobertura k del certificado: | C7: 2
A9: TABLA DE MEDICIONES Y CÁLCULO DE INCERTIDUMBRES
A10: Rango | B10: Valor Patrón | C10: Frecuencia | D10: Unidad | E10: Lect. 1 | F10: Lect. 2 | G10: Lect. 3 | H10: Lect. 4 | I10: Lect. 5 | J10: Promedio | K10: Resolución | L10: Error (E) | M10: u(rep) | N10: u(res) | O10: u(cert) | P10: u(espec) | Q10: u_c | R10: k | S10: U
B11: (Vs) | C11: (Hz) | E11: (Vx1) | F11: (Vx2) | G11: (Vx3) | H11: (Vx4) | I11: (Vx5) | J11: (V̄x) | K11: (dig) | L11: (V̄x - Vs) | M11: Tipo A | N11: Tipo B | O11: Tipo B | P11: Tipo B | Q11: Comb. | S11: Expand.
D12: V | J12: =IF(COUNT(E12:I12)>0,AVERAGE(E12:I12),"") | K12: 0.001 | L12: =IF(J12<>"",J12-B12,"") | M12: =IF(COUNT(E12:I12)>1,STDEV(E12:I12)/SQRT(COUNT(E12:I12)),0) -> 0 | N12: =IF(K12<>"",K12/(2*SQRT(3)),0) -> 0.00028867513 | O12: =IF($C$6<>"",$C$6/$C$7,0) -> 6e-05 | P12: =IF(B12<>"",($C$4*0.000001*ABS(B12)+$C$5*0.000001)/SQRT(3),0) -> 0 | Q12: =IF(J12<>"",SQRT(M12^2+N12^2+O12^2+P12^2),"") | R12: =IF(Q12<>"",2,"") | S12: =IF(Q12<>"",R12*Q12,"")
D13: V | J13: =IF(COUNT(E13:I13)>0,AVERAGE(E13:I13),"") | K13: 0.001 | L13: =IF(J13<>"",J13-B13,"") | M13: =IF(COUNT(E13:I13)>1,STDEV(E13:I13)/SQRT(COUNT(E13:I13)),0) -> 0 | N13: =IF(K13<>"",K13/(2*SQRT(3)),0) -> 0.00028867513 | O13: =IF($C$6<>"",$C$6/$C$7,0) -> 6e-05 | P13: =IF(B13<>"",($C$4*0.000001*ABS(B13)+$C$5*0.000001)/SQRT(3),0) -> 0 | Q13: =IF(J13<>"",SQRT(M13^2+N13^2+O13^2+P13^2),"") | R13: =IF(Q13<>"",2,"") | S13: =IF(Q13<>"",R13*Q13,"")
D14: V | J14: =IF(COUNT(E14:I14)>0,AVERAGE(E14:I14),"") | K14: 0.001 | L14: =IF(J14<>"",J14-B14,"") | M14: =IF(COUNT(E14:I14)>1,STDEV(E14:I14)/SQRT(COUNT(E14:I14)),0) -> 0 | N14: =IF(K14<>"",K14/(2*SQRT(3)),0) -> 0.00028867513 | O14: =IF($C$6<>"",$C$6/$C$7,0) -> 6e-05 | P14: =IF(B14<>"",($C$4*0.000001*ABS(B14)+$C$5*0.000001)/SQRT(3),0) -> 0 | Q14: =IF(J14<>"",SQRT(M14^2+N14^2+O14^2+P14^2),"") | R14: =IF(Q14<>"",2,"") | S14: =IF(Q14<>"",R14*Q14,"")
D15: V | J15: =IF(COUNT(E15:I15)>0,AVERAGE(E15:I15),"") | K15: 0.001 | L15: =IF(J15<>"",J15-B15,"") | M15: =IF(COUNT(E15:I15)>1,STDEV(E15:I15)/SQRT(COUNT(E15:I15)),0) -> 0 | N15: =IF(K15<>"",K15/(2*SQRT(3)),0) -> 0.00028867513 | O15: =IF($C$6<>"",$C$6/$C$7,0) -> 6e-05 | P15: =IF(B15<>"",($C$4*0.000001*ABS(B15)+$C$5*0.000001)/SQRT(3),0) -> 0 | Q15: =IF(J15<>"",SQRT(M15^2+N15^2+O15^2+P15^2),"") | R15: =IF(Q15<>"",2,"") | S15: =IF(Q15<>"",R15*Q15,"")
J16: =IF(COUNT(E16:I16)>0,AVERAGE(E16:I16),"") | L16: =IF(J16<>"",J16-B16,"") | M16: =IF(COUNT(E16:I16)>1,STDEV(E16:I16)/SQRT(COUNT(E16:I16)),0) -> 0 | N16: =IF(K16<>"",K16/(2*SQRT(3)),0) -> 0 | O16: =IF($C$6<>"",$C$6/$C$7,0) -> 6e-05 | P16: =IF(B16<>"",($C$4*0.000001*ABS(B16)+$C$5*0.000001)/SQRT(3),0) -> 0 | Q16: =IF(J16<>"",SQRT(M16^2+N16^2+O16^2+P16^2),"") | R16: =IF(Q16<>"",2,"") | S16: =IF(Q16<>"",R16*Q16,"")
J17: =IF(COUNT(E17:I17)>0,AVERAGE(E17:I17),"") | L17: =IF(J17<>"",J17-B17,"") | M17: =IF(COUNT(E17:I17)>1,STDEV(E17:I17)/SQRT(COUNT(E17:I17)),0) -> 0 | N17: =IF(K17<>"",K17/(2*SQRT(3)),0) -> 0 | O17: =IF($C$6<>"",$C$6/$C$7,0) -> 6e-05 | P17: =IF(B17<>"",($C$4*0.000001*ABS(B17)+$C$5*0.000001)/SQRT(3),0) -> 0 | Q17: =IF(J17<>"",SQRT(M17^2+N17^2+O17^2+P17^2),"") | R17: =IF(Q17<>"",2,"") | S17: =IF(Q17<>"",R17*Q17,"")
J18: =IF(COUNT(E18:I18)>0,AVERAGE(E18:I18),"") | L18: =IF(J18<>"",J18-B18,"") | M18: =IF(COUNT(E18:I18)>1,STDEV(E18:I18)/SQRT(COUNT(E18:I18)),0) -> 0 | N18: =IF(K18<>"",K18/(2*SQRT(3)),0) -> 0 | O18: =IF($C$6<>"",$C$6/$C$7,0) -> 6e-05 | P18: =IF(B18<>"",($C$4*0.000001*ABS(B18)+$C$5*0.000001)/SQRT(3),0) -> 0 | Q18: =IF(J18<>"",SQRT(M18^2+N18^2+O18^2+P18^2),"") | R18: =IF(Q18<>"",2,"") | S18: =IF(Q18<>"",R18*Q18,"")
J19: =IF(COUNT(E19:I19)>0,AVERAGE(E19:I19),"") | L19: =IF(J19<>"",J19-B19,"") | M19: =IF(COUNT(E19:I19)>1,STDEV(E19:I19)/SQRT(COUNT(E19:I19)),0) -> 0 | N19: =IF(K19<>"",K19/(2*SQRT(3)),0) -> 0 | O19: =IF($C$6<>"",$C$6/$C$7,0) -> 6e-05 | P19: =IF(B19<>"",($C$4*0.000001*ABS(B19)+$C$5*0.000001)/SQRT(3),0) -> 0 | Q19: =IF(J19<>"",SQRT(M19^2+N19^2+O19^2+P19^2),"") | R19: =IF(Q19<>"",2,"") | S19: =IF(Q19<>"",R19*Q19,"")
J20: =IF(COUNT(E20:I20)>0,AVERAGE(E20:I20),"") | L20: =IF(J20<>"",J20-B20,"") | M20: =IF(COUNT(E20:I20)>1,STDEV(E20:I20)/SQRT(COUNT(E20:I20)),0) -> 0 | N20: =IF(K20<>"",K20/(2*SQRT(3)),0) -> 0 | O20: =IF($C$6<>"",$C$6/$C$7,0) -> 6e-05 | P20: =IF(B20<>"",($C$4*0.000001*ABS(B20)+$C$5*0.000001)/SQRT(3),0) -> 0 | Q20: =IF(J20<>"",SQRT(M20^2+N20^2+O20^2+P20^2),"") | R20: =IF(Q20<>"",2,"") | S20: =IF(Q20<>"",R20*Q20,"")
J21: =IF(COUNT(E21:I21)>0,AVERAGE(E21:I21),"") | L21: =IF(J21<>"",J21-B21,"") | M21: =IF(COUNT(E21:I21)>1,STDEV(E21:I21)/SQRT(COUNT(E21:I21)),0) -> 0 | N21: =IF(K21<>"",K21/(2*SQRT(3)),0) -> 0 | O21: =IF($C$6<>"",$C$6/$C$7,0) -> 6e-05 | P21: =IF(B21<>"",($C$4*0.000001*ABS(B21)+$C$5*0.000001)/SQRT(3),0) -> 0 | Q21: =IF(J21<>"",SQRT(M21^2+N21^2+O21^2+P21^2),"") | R21: =IF(Q21<>"",2,"") | S21: =IF(Q21<>"",R21*Q21,"")

Sheet Corriente DC
A1: CALIBRACIÓN EN CORRIENTE CONTINUA (DC)
A3: PARÁMETROS DEL PATRÓN
A4: Especificación del fabricante (ppm de lectura): | C4: 50
A5: Especificación del fabricante (µA offset): | C5: 10
A6: Incertidumbre certificado patrón U: | C6: 1e-05 | D6: A
A7: Factor de cobertura k del certificado: | C7: 2
A9: TABLA DE MEDICIONES Y CÁLCULO DE INCERTIDUMBRES INA3
A10: Rango | B10: Valor Patrón | C10: Unidad | D10: Lect. 1 | E10: Lect. 2 | F10: Lect. 3 | G10: Lect. 4 | H10: Lect. 5 | I10: Promedio | J10: Resolución | K10: Error (E) | L10: u(rep) | M10: u(res) | N10: u(cert) | O10: u(espec) | P10: u_c | Q10: k | R10: U
A12: 10 mA | B12: 10.46 | C12: mA | D12: 10.13 | E12: 10.2 | F12: 10.32 | G12: 9.65 | H12: 10.31 | I12: =IF(COUNT(D12:H12)>0,AVERAGE(D12:H12),"") -> 10.122 | J12: 1e-06 | K12: =IF(I12<>"",I12-B12,"") -> -0.338 | L12: =IF(COUNT(D12:H12)>1,STDEV(D12:H12)/SQRT(COUNT(D12:H12)),0) -> 0.12318279 | M12: =IF(J12<>"",J12/(2*SQRT(3)),0) -> 2.8867513e-07 | N12: =IF($C$6<>"",$C$6/$C$7,0) -> 5e-06 | O12: =IF(B12<>"",($C$4*0.000001*ABS(B12)+$C$5*0.000001)/SQRT(3),0) -> 0.00030772769 | P12: =IF(I12<>"",SQRT(L12^2+M12^2+N12^2+O12^2),"") -> 0.12318318 | Q12: =IF(P12<>"",2,"") -> 2 | R12: =IF(P12<>"",Q12*P12,"") -> 0.24636635
A13: 250 mA | B13: 246.926 | C13: mA | D13: 246.82 | E13: 247.16 | F13: 247.56 | G13: 246.07 | H13: 247.43 | I13: =IF(COUNT(D13:H13)>0,AVERAGE(D13:H13),"") -> 247.008 | J13: 1e-05 | K13: =IF(I13<>"",I13-B13,"") -> 0.082 | L13: =IF(COUNT(D13:H13)>1,STDEV(D13:H13)/SQRT(COUNT(D13:H13)),0) -> 0.26655956 | M13: =IF(J13<>"",J13/(2*SQRT(3)),0) -> 2.8867513e-06 | N13: =IF($C$6<>"",$C$6/$C$7,0) -> 5e-06 | O13: =IF(B13<>"",($C$4*0.000001*ABS(B13)+$C$5*0.000001)/SQRT(3),0) -> 0.0071339131 | P13: =IF(I13<>"",SQRT(L13^2+M13^2+N13^2+O13^2),"") -> 0.26665501 | Q13: =IF(P13<>"",2,"") -> 2 | R13: =IF(P13<>"",Q13*P13,"") -> 0.53331001
A14: 500 mA | B14: 493.951 | C14: mA | D14: 494.81 | E14: 491.81 | F14: 494.83 | G14: 494.58 | H14: 494.56 | I14: =IF(COUNT(D14:H14)>0,AVERAGE(D14:H14),"") -> 494.118 | J14: 0.0001 | K14: =IF(I14<>"",I14-B14,"") -> 0.167 | L14: =IF(COUNT(D14:H14)>1,STDEV(D14:H14)/SQRT(COUNT(D14:H14)),0) -> 0.5797189 | M14: =IF(J14<>"",J14/(2*SQRT(3)),0) -> 2.8867513e-05 | N14: =IF($C$6<>"",$C$6/$C$7,0) -> 5e-06 | O14: =IF(B14<>"",($C$4*0.000001*ABS(B14)+$C$5*0.000001)/SQRT(3),0) -> 0.014264911 | P14: =IF(I14<>"",SQRT(L14^2+M14^2+N14^2+O14^2),"") -> 0.57989438 | Q14: =IF(P14<>"",2,"") -> 2 | R14: =IF(P14<>"",Q14*P14,"") -> 1.1597888
A15: 1,0 A | B15: 989.443 | C15: mA | D15: 996.6 | E15: 996.74 | F15: 996.66 | G15: 996.83 | H15: 996.92 | I15: =IF(COUNT(D15:H15)>0,AVERAGE(D15:H15),"") -> 996.75 | J15: 0.001 | K15: =IF(I15<>"",I15-B15,"") -> 7.307 | L15: =IF(COUNT(D15:H15)>1,STDEV(D15:H15)/SQRT(COUNT(D15:H15)),0) -> 0.057445626 | M15: =IF(J15<>"",J15/(2*SQRT(3)),0) -> 0.00028867513 | N15: =IF($C$6<>"",$C$6/$C$7,0) -> 5e-06 | O15: =IF(B15<>"",($C$4*0.000001*ABS(B15)+$C$5*0.000001)/SQRT(3),0) -> 0.028568533 | P15: =IF(I15<>"",SQRT(L15^2+M15^2+N15^2+O15^2),"") -> 0.064157965 | Q15: =IF(P15<>"",2,"") -> 2 | R15: =IF(P15<>"",Q15*P15,"") -> 0.12831593
A16: 2,0 A | B16: 1986.89 | C16: mA | D16: 2053.92 | E16: 2054.26 | F16: 2054.43 | G16: 2054.57 | H16: 2055.11 | I16: =IF(COUNT(D16:H16)>0,AVERAGE(D16:H16),"") -> 2054.458 | J16: 0.01 | K16: =IF(I16<>"",I16-B16,"") -> 67.568 | L16: =IF(COUNT(D16:H16)>1,STDEV(D16:H16)/SQRT(COUNT(D16:H16)),0) -> 0.19584177 | M16: =IF(J16<>"",J16/(2*SQRT(3)),0) -> 0.0028867513 | N16: =IF($C$6<>"",$C$6/$C$7,0) -> 5e-06 | O16: =IF(B16<>"",($C$4*0.000001*ABS(B16)+$C$5*0.000001)/SQRT(3),0) -> 0.057362347 | P16: =IF(I16<>"",SQRT(L16^2+M16^2+N16^2+O16^2),"") -> 0.20409011 | Q16: =IF(P16<>"",2,"") -> 2 | R16: =IF(P16<>"",Q16*P16,"") -> 0.40818022
I17: =IF(COUNT(D17:H17)>0,AVERAGE(D17:H17),"") | K17: =IF(I17<>"",I17-B17,"") | L17: =IF(COUNT(D17:H17)>1,STDEV(D17:H17)/SQRT(COUNT(D17:H17)),0) -> 0 | M17: =IF(J17<>"",J17/(2*SQRT(3)),0) -> 0 | N17: =IF($C$6<>"",$C$6/$C$7,0) -> 5e-06 | O17: =IF(B17<>"",($C$4*0.000001*ABS(B17)+$C$5*0.000001)/SQRT(3),0) -> 0 | P17: =IF(I17<>"",SQRT(L17^2+M17^2+N17^2+O17^2),"") | Q17: =IF(P17<>"",2,"") | R17: =IF(P17<>"",Q17*P17,"")
I18: =IF(COUNT(D18:H18)>0,AVERAGE(D18:H18),"") | K18: =IF(I18<>"",I18-B18,"") | L18: =IF(COUNT(D18:H18)>1,STDEV(D18:H18)/SQRT(COUNT(D18:H18)),0) -> 0 | M18: =IF(J18<>"",J18/(2*SQRT(3)),0) -> 0 | N18: =IF($C$6<>"",$C$6/$C$7,0) -> 5e-06 | O18: =IF(B18<>"",($C$4*0.000001*ABS(B18)+$C$5*0.000001)/SQRT(3),0) -> 0 | P18: =IF(I18<>"",SQRT(L18^2+M18^2+N18^2+O18^2),"") | Q18: =IF(P18<>"",2,"") | R18: =IF(P18<>"",Q18*P18,"")
I19: =IF(COUNT(D19:H19)>0,AVERAGE(D19:H19),"") | K19: =IF(I19<>"",I19-B19,"") | L19: =IF(COUNT(D19:H19)>1,STDEV(D19:H19)/SQRT(COUNT(D19:H19)),0) -> 0 | M19: =IF(J19<>"",J19/(2*SQRT(3)),0) -> 0 | N19: =IF($C$6<>"",$C$6/$C$7,0) -> 5e-06 | O19: =IF(B19<>"",($C$4*0.000001*ABS(B19)+$C$5*0.000001)/SQRT(3),0) -> 0 | P19: =IF(I19<>"",SQRT(L19^2+M19^2+N19^2+O19^2),"") | Q19: =IF(P19<>"",2,"") | R19: =IF(P19<>"",Q19*P19,"")
I20: =IF(COUNT(D20:H20)>0,AVERAGE(D20:H20),"") | K20: =IF(I20<>"",I20-B20,"") | L20: =IF(COUNT(D20:H20)>1,STDEV(D20:H20)/SQRT(COUNT(D20:H20)),0) -> 0 | M20: =IF(J20<>"",J20/(2*SQRT(3)),0) -> 0 | N20: =IF($C$6<>"",$C$6/$C$7,0) -> 5e-06 | O20: =IF(B20<>"",($C$4*0.000001*ABS(B20)+$C$5*0.000001)/SQRT(3),0) -> 0 | P20: =IF(I20<>"",SQRT(L20^2+M20^2+N20^2+O20^2),"") | Q20: =IF(P20<>"",2,"") | R20: =IF(P20<>"",Q20*P20,"")
I21: =IF(COUNT(D21:H21)>0,AVERAGE(D21:H21),"") | K21: =IF(I21<>"",I21-B21,"") | L21: =IF(COUNT(D21:H21)>1,STDEV(D21:H21)/SQRT(COUNT(D21:H21)),0) -> 0 | M21: =IF(J21<>"",J21/(2*SQRT(3)),0) -> 0 | N21: =IF($C$6<>"",$C$6/$C$7,0) -> 5e-06 | O21: =IF(B21<>"",($C$4*0.000001*ABS(B21)+$C$5*0.000001)/SQRT(3),0) -> 0 | P21: =IF(I21<>"",SQRT(L21^2+M21^2+N21^2+O21^2),"") | Q21: =IF(P21<>"",2,"") | R21: =IF(P21<>"",Q21*P21,"")

Sheet Corriente AC
A1: CALIBRACIÓN EN CORRIENTE ALTERNA (AC)
A3: PARÁMETROS DEL PATRÓN
A4: Especificación del fabricante (ppm de lectura): | C4: 100
A5: Especificación del fabricante (µA offset): | C5: 50
A6: Incertidumbre certificado patrón U: | C6: 5e-05 | D6: A
A7: Factor de cobertura k del certificado: | C7: 2
A9: TABLA DE MEDICIONES Y CÁLCULO DE INCERTIDUMBRES
A10: Rango | B10: Valor Patrón | C10: Frecuencia | D10: Unidad | E10: Lect. 1 | F10: Lect. 2 | G10: Lect. 3 | H10: Lect. 4 | I10: Lect. 5 | J10: Promedio | K10: Resolución | L10: Error (E) | M10: u(rep) | N10: u(res) | O10: u(cert) | P10: u(espec) | Q10: u_c | R10: k | S10: U
A12: 500 mA | B12: 0.5 | C12: 60 | D12: A | J12: =IF(COUNT(E12:I12)>0,AVERAGE(E12:I12),"") | K12: 0.001 | L12: =IF(J12<>"",J12-B12,"") | M12: =IF(COUNT(E12:I12)>1,STDEV(E12:I12)/SQRT(COUNT(E12:I12)),0) -> 0 | N12: =IF(K12<>"",K12/(2*SQRT(3)),0) -> 0.00028867513 | O12: =IF($C$6<>"",$C$6/$C$7,0) -> 2.5e-05 | P12: =IF(B12<>"",($C$4*0.000001*ABS(B12)+$C$5*0.000001)/SQRT(3),0) -> 5.7735027e-05 | Q12: =IF(J12<>"",SQRT(M12^2+N12^2+O12^2+P12^2),"") | R12: =IF(Q12<>"",2,"") | S12: =IF(Q12<>"",R12*Q12,"")
A13: 500 mA | B13: 0.5 | C13: 1000 | D13: A | J13: =IF(COUNT(E13:I13)>0,AVERAGE(E13:I13),"") | K13: 0.001 | L13: =IF(J13<>"",J13-B13,"") | M13: =IF(COUNT(E13:I13)>1,STDEV(E13:I13)/SQRT(COUNT(E13:I13)),0) -> 0 | N13: =IF(K13<>"",K13/(2*SQRT(3)),0) -> 0.00028867513 | O13: =IF($C$6<>"",$C$6/$C$7,0) -> 2.5e-05 | P13: =IF(B13<>"",($C$4*0.000001*ABS(B13)+$C$5*0.000001)/SQRT(3),0) -> 5.7735027e-05 | Q13: =IF(J13<>"",SQRT(M13^2+N13^2+O13^2+P13^2),"") | R13: =IF(Q13<>"",2,"") | S13: =IF(Q13<>"",R13*Q13,"")
J14: =IF(COUNT(E14:I14)>0,AVERAGE(E14:I14),"") | L14: =IF(J14<>"",J14-B14,"") | M14: =IF(COUNT(E14:I14)>1,STDEV(E14:I14)/SQRT(COUNT(E14:I14)),0) -> 0 | N14: =IF(K14<>"",K14/(2*SQRT(3)),0) -> 0 | O14: =IF($C$6<>"",$C$6/$C$7,0) -> 2.5e-05 | P14: =IF(B14<>"",($C$4*0.000001*ABS(B14)+$C$5*0.000001)/SQRT(3),0) -> 0 | Q14: =IF(J14<>"",SQRT(M14^2+N14^2+O14^2+P14^2),"") | R14: =IF(Q14<>"",2,"") | S14: =IF(Q14<>"",R14*Q14,"")
J15: =IF(COUNT(E15:I15)>0,AVERAGE(E15:I15),"") | L15: =IF(J15<>"",J15-B15,"") | M15: =IF(COUNT(E15:I15)>1,STDEV(E15:I15)/SQRT(COUNT(E15:I15)),0) -> 0 | N15: =IF(K15<>"",K15/(2*SQRT(3)),0) -> 0 | O15: =IF($C$6<>"",$C$6/$C$7,0) -> 2.5e-05 | P15: =IF(B15<>"",($C$4*0.000001*ABS(B15)+$C$5*0.000001)/SQRT(3),0) -> 0 | Q15: =IF(J15<>"",SQRT(M15^2+N15^2+O15^2+P15^2),"") | R15: =IF(Q15<>"",2,"") | S15: =IF(Q15<>"",R15*Q15,"")
J16: =IF(COUNT(E16:I16)>0,AVERAGE(E16:I16),"") | L16: =IF(J16<>"",J16-B16,"") | M16: =IF(COUNT(E16:I16)>1,STDEV(E16:I16)/SQRT(COUNT(E16:I16)),0) -> 0 | N16: =IF(K16<>"",K16/(2*SQRT(3)),0) -> 0 | O16: =IF($C$6<>"",$C$6/$C$7,0) -> 2.5e-05 | P16: =IF(B16<>"",($C$4*0.000001*ABS(B16)+$C$5*0.000001)/SQRT(3),0) -> 0 | Q16: =IF(J16<>"",SQRT(M16^2+N16^2+O16^2+P16^2),"") | R16: =IF(Q16<>"",2,"") | S16: =IF(Q16<>"",R16*Q16,"")
J17: =IF(COUNT(E17:I17)>0,AVERAGE(E17:I17),"") | L17: =IF(J17<>"",J17-B17,"") | M17: =IF(COUNT(E17:I17)>1,STDEV(E17:I17)/SQRT(COUNT(E17:I17)),0) -> 0 | N17: =IF(K17<>"",K17/(2*SQRT(3)),0) -> 0 | O17: =IF($C$6<>"",$C$6/$C$7,0) -> 2.5e-05 | P17: =IF(B17<>"",($C$4*0.000001*ABS(B17)+$C$5*0.000001)/SQRT(3),0) -> 0 | Q17: =IF(J17<>"",SQRT(M17^2+N17^2+O17^2+P17^2),"") | R17: =IF(Q17<>"",2,"") | S17: =IF(Q17<>"",R17*Q17,"")
J18: =IF(COUNT(E18:I18)>0,AVERAGE(E18:I18),"") | L18: =IF(J18<>"",J18-B18,"") | M18: =IF(COUNT(E18:I18)>1,STDEV(E18:I18)/SQRT(COUNT(E18:I18)),0) -> 0 | N18: =IF(K18<>"",K18/(2*SQRT(3)),0) -> 0 | O18: =IF($C$6<>"",$C$6/$C$7,0) -> 2.5e-05 | P18: =IF(B18<>"",($C$4*0.000001*ABS(B18)+$C$5*0.000001)/SQRT(3),0) -> 0 | Q18: =IF(J18<>"",SQRT(M18^2+N18^2+O18^2+P18^2),"") | R18: =IF(Q18<>"",2,"") | S18: =IF(Q18<>"",R18*Q18,"")
J19: =IF(COUNT(E19:I19)>0,AVERAGE(E19:I19),"") | L19: =IF(J19<>"",J19-B19,"") | M19: =IF(COUNT(E19:I19)>1,STDEV(E19:I19)/SQRT(COUNT(E19:I19)),0) -> 0 | N19: =IF(K19<>"",K19/(2*SQRT(3)),0) -> 0 | O19: =IF($C$6<>"",$C$6/$C$7,0) -> 2.5e-05 | P19: =IF(B19<>"",($C$4*0.000001*ABS(B19)+$C$5*0.000001)/SQRT(3),0) -> 0 | Q19: =IF(J19<>"",SQRT(M19^2+N19^2+O19^2+P19^2),"") | R19: =IF(Q19<>"",2,"") | S19: =IF(Q19<>"",R19*Q19,"")
J20: =IF(COUNT(E20:I20)>0,AVERAGE(E20:I20),"") | L20: =IF(J20<>"",J20-B20,"") | M20: =IF(COUNT(E20:I20)>1,STDEV(E20:I20)/SQRT(COUNT(E20:I20)),0) -> 0 | N20: =IF(K20<>"",K20/(2*SQRT(3)),0) -> 0 | O20: =IF($C$6<>"",$C$6/$C$7,0) -> 2.5e-05 | P20: =IF(B20<>"",($C$4*0.000001*ABS(B20)+$C$5*0.000001)/SQRT(3),0) -> 0 | Q20: =IF(J20<>"",SQRT(M20^2+N20^2+O20^2+P20^2),"") | R20: =IF(Q20<>"",2,"") | S20: =IF(Q20<>"",R20*Q20,"")
J21: =IF(COUNT(E21:I21)>0,AVERAGE(E21:I21),"") | L21: =IF(J21<>"",J21-B21,"") | M21: =IF(COUNT(E21:I21)>1,STDEV(E21:I21)/SQRT(COUNT(E21:I21)),0) -> 0 | N21: =IF(K21<>"",K21/(2*SQRT(3)),0) -> 0 | O21: =IF($C$6<>"",$C$6/$C$7,0) -> 2.5e-05 | P21: =IF(B21<>"",($C$4*0.000001*ABS(B21)+$C$5*0.000001)/SQRT(3),0) -> 0 | Q21: =IF(J21<>"",SQRT(M21^2+N21^2+O21^2+P21^2),"") | R21: =IF(Q21<>"",2,"") | S21: =IF(Q21<>"",R21*Q21,"")

Sheet Resistencia
A1: CALIBRACIÓN EN RESISTENCIA (Ω)
A3: PARÁMETROS DEL PATRÓN
A4: Especificación del fabricante (ppm de lectura): | C4: 30
A5: Especificación del fabricante (mΩ offset): | C5: 5
A6: Incertidumbre certificado patrón U: | C6: 0.001 | D6: Ω
A7: Factor de cobertura k del certificado: | C7: 2
A9: TABLA DE MEDICIONES Y CÁLCULO DE INCERTIDUMBRES
A10: Rango | B10: Valor Patrón | C10: Unidad | D10: Lect. 1 | E10: Lect. 2 | F10: Lect. 3 | G10: Lect. 4 | H10: Lect. 5 | I10: Promedio | J10: Resolución | K10: Error (E) | L10: u(rep) | M10: u(res) | N10: u(cert) | O10: u(espec) | P10: u_c | Q10: k | R10: U
A12: 500 Ω | B12: 500 | C12: Ω | I12: =IF(COUNT(D12:H12)>0,AVERAGE(D12:H12),"") | J12: 0.1 | K12: =IF(I12<>"",I12-B12,"") | L12: =IF(COUNT(D12:H12)>1,STDEV(D12:H12)/SQRT(COUNT(D12:H12)),0) -> 0 | M12: =IF(J12<>"",J12/(2*SQRT(3)),0) -> 0.028867513 | N12: =IF($C$6<>"",$C$6/$C$7,0) -> 0.0005 | O12: =IF(B12<>"",($C$4*0.000001*ABS(B12)+$C$5*0.001)/SQRT(3),0) -> 0.011547005 | P12: =IF(I12<>"",SQRT(L12^2+M12^2+N12^2+O12^2),"") | Q12: =IF(P12<>"",2,"") | R12: =IF(P12<>"",Q12*P12,"")
A13: 5 kΩ | B13: 5000 | C13: Ω | I13: =IF(COUNT(D13:H13)>0,AVERAGE(D13:H13),"") | J13: 1 | K13: =IF(I13<>"",I13-B13,"") | L13: =IF(COUNT(D13:H13)>1,STDEV(D13:H13)/SQRT(COUNT(D13:H13)),0) -> 0 | M13: =IF(J13<>"",J13/(2*SQRT(3)),0) -> 0.28867513 | N13: =IF($C$6<>"",$C$6/$C$7,0) -> 0.0005 | O13: =IF(B13<>"",($C$4*0.000001*ABS(B13)+$C$5*0.001)/SQRT(3),0) -> 0.089489292 | P13: =IF(I13<>"",SQRT(L13^2+M13^2+N13^2+O13^2),"") | Q13: =IF(P13<>"",2,"") | R13: =IF(P13<>"",Q13*P13,"")
A14: 50 kΩ | B14: 50000 | C14: Ω | I14: =IF(COUNT(D14:H14)>0,AVERAGE(D14:H14),"") | J14: 10 | K14: =IF(I14<>"",I14-B14,"") | L14: =IF(COUNT(D14:H14)>1,STDEV(D14:H14)/SQRT(COUNT(D14:H14)),0) -> 0 | M14: =IF(J14<>"",J14/(2*SQRT(3)),0) -> 2.8867513 | N14: =IF($C$6<>"",$C$6/$C$7,0) -> 0.0005 | O14: =IF(B14<>"",($C$4*0.000001*ABS(B14)+$C$5*0.001)/SQRT(3),0) -> 0.86891216 | P14: =IF(I14<>"",SQRT(L14^2+M14^2+N14^2+O14^2),"") | Q14: =IF(P14<>"",2,"") | R14: =IF(P14<>"",Q14*P14,"")
A15: 500 kΩ | B15: 500000 | C15: Ω | I15: =IF(COUNT(D15:H15)>0,AVERAGE(D15:H15),"") | J15: 100 | K15: =IF(I15<>"",I15-B15,"") | L15: =IF(COUNT(D15:H15)>1,STDEV(D15:H15)/SQRT(COUNT(D15:H15)),0) -> 0 | M15: =IF(J15<>"",J15/(2*SQRT(3)),0) -> 28.867513 | N15: =IF($C$6<>"",$C$6/$C$7,0) -> 0.0005 | O15: =IF(B15<>"",($C$4*0.000001*ABS(B15)+$C$5*0.001)/SQRT(3),0) -> 8.6631408 | P15: =IF(I15<>"",SQRT(L15^2+M15^2+N15^2+O15^2),"") | Q15: =IF(P15<>"",2,"") | R15: =IF(P15<>"",Q15*P15,"")
A16: 5 MΩ | B16: 5000000 | C16: Ω | I16: =IF(COUNT(D16:H16)>0,AVERAGE(D16:H16),"") | J16: 1000 | K16: =IF(I16<>"",I16-B16,"") | L16: =IF(COUNT(D16:H16)>1,STDEV(D16:H16)/SQRT(COUNT(D16:H16)),0) -> 0 | M16: =IF(J16<>"",J16/(2*SQRT(3)),0) -> 288.67513 | N16: =IF($C$6<>"",$C$6/$C$7,0) -> 0.0005 | O16: =IF(B16<>"",($C$4*0.000001*ABS(B16)+$C$5*0.001)/SQRT(3),0) -> 86.605427 | P16: =IF(I16<>"",SQRT(L16^2+M16^2+N16^2+O16^2),"") | Q16: =IF(P16<>"",2,"") | R16: =IF(P16<>"",Q16*P16,"")
I17: =IF(COUNT(D17:H17)>0,AVERAGE(D17:H17),"") | K17: =IF(I17<>"",I17-B17,"") | L17: =IF(COUNT(D17:H17)>1,STDEV(D17:H17)/SQRT(COUNT(D17:H17)),0) -> 0 | M17: =IF(J17<>"",J17/(2*SQRT(3)),0) -> 0 | N17: =IF($C$6<>"",$C$6/$C$7,0) -> 0.0005 | O17: =IF(B17<>"",($C$4*0.000001*ABS(B17)+$C$5*0.001)/SQRT(3),0) -> 0 | P17: =IF(I17<>"",SQRT(L17^2+M17^2+N17^2+O17^2),"") | Q17: =IF(P17<>"",2,"") | R17: =IF(P17<>"",Q17*P17,"")
I18: =IF(COUNT(D18:H18)>0,AVERAGE(D18:H18),"") | K18: =IF(I18<>"",I18-B18,"") | L18: =IF(COUNT(D18:H18)>1,STDEV(D18:H18)/SQRT(COUNT(D18:H18)),0) -> 0 | M18: =IF(J18<>"",J18/(2*SQRT(3)),0) -> 0 | N18: =IF($C$6<>"",$C$6/$C$7,0) -> 0.0005 | O18: =IF(B18<>"",($C$4*0.000001*ABS(B18)+$C$5*0.001)/SQRT(3),0) -> 0 | P18: =IF(I18<>"",SQRT(L18^2+M18^2+N18^2+O18^2),"") | Q18: =IF(P18<>"",2,"") | R18: =IF(P18<>"",Q18*P18,"")
I19: =IF(COUNT(D19:H19)>0,AVERAGE(D19:H19),"") | K19: =IF(I19<>"",I19-B19,"") | L19: =IF(COUNT(D19:H19)>1,STDEV(D19:H19)/SQRT(COUNT(D19:H19)),0) -> 0 | M19: =IF(J19<>"",J19/(2*SQRT(3)),0) -> 0 | N19: =IF($C$6<>"",$C$6/$C$7,0) -> 0.0005 | O19: =IF(B19<>"",($C$4*0.000001*ABS(B19)+$C$5*0.001)/SQRT(3),0) -> 0 | P19: =IF(I19<>"",SQRT(L19^2+M19^2+N19^2+O19^2),"") | Q19: =IF(P19<>"",2,"") | R19: =IF(P19<>"",Q19*P19,"")
I20: =IF(COUNT(D20:H20)>0,AVERAGE(D20:H20),"") | K20: =IF(I20<>"",I20-B20,"") | L20: =IF(COUNT(D20:H20)>1,STDEV(D20:H20)/SQRT(COUNT(D20:H20)),0) -> 0 | M20: =IF(J20<>"",J20/(2*SQRT(3)),0) -> 0 | N20: =IF($C$6<>"",$C$6/$C$7,0) -> 0.0005 | O20: =IF(B20<>"",($C$4*0.000001*ABS(B20)+$C$5*0.001)/SQRT(3),0) -> 0 | P20: =IF(I20<>"",SQRT(L20^2+M20^2+N20^2+O20^2),"") | Q20: =IF(P20<>"",2,"") | R20: =IF(P20<>"",Q20*P20,"")
I21: =IF(COUNT(D21:H21)>0,AVERAGE(D21:H21),"") | K21: =IF(I21<>"",I21-B21,"") | L21: =IF(COUNT(D21:H21)>1,STDEV(D21:H21)/SQRT(COUNT(D21:H21)),0) -> 0 | M21: =IF(J21<>"",J21/(2*SQRT(3)),0) -> 0 | N21: =IF($C$6<>"",$C$6/$C$7,0) -> 0.0005 | O21: =IF(B21<>"",($C$4*0.000001*ABS(B21)+$C$5*0.001)/SQRT(3),0) -> 0 | P21: =IF(I21<>"",SQRT(L21^2+M21^2+N21^2+O21^2),"") | Q21: =IF(P21<>"",2,"") | R21: =IF(P21<>"",Q21*P21,"")

Sheet Capacitancia
A1: CALIBRACIÓN EN CAPACITANCIA (F)
A3: PARÁMETROS DEL PATRÓN
A4: Especificación del fabricante (ppm de lectura): | C4: 100
A5: Especificación del fabricante (pF offset): | C5: 0.5
A6: Incertidumbre certificado patrón U: | C6: 1e-05 | D6: F
A7: Factor de cobertura k del certificado: | C7: 2
A9: TABLA DE MEDICIONES Y CÁLCULO DE INCERTIDUMBRES
A10: Rango | B10: Valor Patrón | C10: Unidad | D10: Lect. 1 | E10: Lect. 2 | F10: Lect. 3 | G10: Lect. 4 | H10: Lect. 5 | I10: Promedio | J10: Resolución | K10: Error (E) | L10: u(rep) | M10: u(res) | N10: u(cert) | O10: u(espec) | P10: u_c | Q10: k | R10: U
B11: (Cs) | D11: (Cx1) | E11: (Cx2) | F11: (Cx3) | G11: (Cx4) | H11: (Cx5) | I11: (C̄x) | J11: (dig) | K11: (C̄x - Cs) | L11: Tipo A | M11: Tipo B | N11: Tipo B | O11: Tipo B | P11: Comb. | R11: Expand.
A12: 1 nF | B12: 1e-09 | C12: F | I12: =IF(COUNT(D12:H12)>0,AVERAGE(D12:H12),"") | J12: 1e-12 | K12: =IF(I12<>"",I12-B12,"") | L12: =IF(COUNT(D12:H12)>1,_xlfn.STDEV.S(D12:H12)/SQRT(COUNT(D12:H12)),0) -> 0 | M12: =J12/(2*SQRT(3)) -> 2.8867513e-13 | N12: =$C$6/$C$7 -> 5e-06 | O12: =($C$4/1000000*ABS(B12)+$C$5*0.000000000001)/SQRT(3) -> 3.4641016e-13 | P12: =IF(I12<>"",SQRT(L12^2+M12^2+N12^2+O12^2),"") | Q12: =IF(P12<>"",2,"") | R12: =IF(P12<>"",Q12*P12,"")
A13: 10 nF | B13: 1e-08 | C13: F | I13: =IF(COUNT(D13:H13)>0,AVERAGE(D13:H13),"") | J13: 1e-11 | K13: =IF(I13<>"",I13-B13,"") | L13: =IF(COUNT(D13:H13)>1,_xlfn.STDEV.S(D13:H13)/SQRT(COUNT(D13:H13)),0) -> 0 | M13: =J13/(2*SQRT(3)) -> 2.8867513e-12 | N13: =$C$6/$C$7 -> 5e-06 | O13: =($C$4/1000000*ABS(B13)+$C$5*0.000000000001)/SQRT(3) -> 8.660254e-13 | P13: =IF(I13<>"",SQRT(L13^2+M13^2+N13^2+O13^2),"") | Q13: =IF(P13<>"",2,"") | R13: =IF(P13<>"",Q13*P13,"")
A14: 100 nF | B14: 1e-07 | C14: F | I14: =IF(COUNT(D14:H14)>0,AVERAGE(D14:H14),"") | J14: 1e-10 | K14: =IF(I14<>"",I14-B14,"") | L14: =IF(COUNT(D14:H14)>1,_xlfn.STDEV.S(D14:H14)/SQRT(COUNT(D14:H14)),0) -> 0 | M14: =J14/(2*SQRT(3)) -> 2.8867513e-11 | N14: =$C$6/$C$7 -> 5e-06 | O14: =($C$4/1000000*ABS(B14)+$C$5*0.000000000001)/SQRT(3) -> 6.0621778e-12 | P14: =IF(I14<>"",SQRT(L14^2+M14^2+N14^2+O14^2),"") | Q14: =IF(P14<>"",2,"") | R14: =IF(P14<>"",Q14*P14,"")
A15: 1 µF | B15: 1e-06 | C15: F | I15: =IF(COUNT(D15:H15)>0,AVERAGE(D15:H15),"") | J15: 1e-09 | K15: =IF(I15<>"",I15-B15,"") | L15: =IF(COUNT(D15:H15)>1,_xlfn.STDEV.S(D15:H15)/SQRT(COUNT(D15:H15)),0) -> 0 | M15: =J15/(2*SQRT(3)) -> 2.8867513e-10 | N15: =$C$6/$C$7 -> 5e-06 | O15: =($C$4/1000000*ABS(B15)+$C$5*0.000000000001)/SQRT(3) -> 5.8023702e-11 | P15: =IF(I15<>"",SQRT(L15^2+M15^2+N15^2+O15^2),"") | Q15: =IF(P15<>"",2,"") | R15: =IF(P15<>"",Q15*P15,"")
A16: 10 µF | B16: 1e-05 | C16: F | I16: =IF(COUNT(D16:H16)>0,AVERAGE(D16:H16),"") | J16: 1e-08 | K16: =IF(I16<>"",I16-B16,"") | L16: =IF(COUNT(D16:H16)>1,_xlfn.STDEV.S(D16:H16)/SQRT(COUNT(D16:H16)),0) -> 0 | M16: =J16/(2*SQRT(3)) -> 2.8867513e-09 | N16: =$C$6/$C$7 -> 5e-06 | O16: =($C$4/1000000*ABS(B16)+$C$5*0.000000000001)/SQRT(3) -> 5.7763894e-10 | P16: =IF(I16<>"",SQRT(L16^2+M16^2+N16^2+O16^2),"") | Q16: =IF(P16<>"",2,"") | R16: =IF(P16<>"",Q16*P16,"")
A17: 100 µF | B17: 0.0001 | C17: F | I17: =IF(COUNT(D17:H17)>0,AVERAGE(D17:H17),"") | J17: 1e-07 | K17: =IF(I17<>"",I17-B17,"") | L17: =IF(COUNT(D17:H17)>1,_xlfn.STDEV.S(D17:H17)/SQRT(COUNT(D17:H17)),0) -> 0 | M17: =J17/(2*SQRT(3)) -> 2.8867513e-08 | N17: =$C$6/$C$7 -> 5e-06 | O17: =($C$4/1000000*ABS(B17)+$C$5*0.000000000001)/SQRT(3) -> 5.7737914e-09 | P17: =IF(I17<>"",SQRT(L17^2+M17^2+N17^2+O17^2),"") | Q17: =IF(P17<>"",2,"") | R17: =IF(P17<>"",Q17*P17,"")
A18: 1000 µF | B18: 0.001 | C18: F | I18: =IF(COUNT(D18:H18)>0,AVERAGE(D18:H18),"") | J18: 1e-06 | K18: =IF(I18<>"",I18-B18,"") | L18: =IF(COUNT(D18:H18)>1,_xlfn.STDEV.S(D18:H18)/SQRT(COUNT(D18:H18)),0) -> 0 | M18: =J18/(2*SQRT(3)) -> 2.8867513e-07 | N18: =$C$6/$C$7 -> 5e-06 | O18: =($C$4/1000000*ABS(B18)+$C$5*0.000000000001)/SQRT(3) -> 5.7735316e-08 | P18: =IF(I18<>"",SQRT(L18^2+M18^2+N18^2+O18^2),"") | Q18: =IF(P18<>"",2,"") | R18: =IF(P18<>"",Q18*P18,"")

Sheet Frecuencia
A1: CALIBRACIÓN EN FRECUENCIA (Hz)
A3: PARÁMETROS DEL PATRÓN
A4: Especificación del fabricante (ppm de lectura): | C4: 5
A5: Especificación del fabricante (Hz offset): | C5: 0.01
A6: Incertidumbre certificado patrón U: | C6: 0.001 | D6: Hz
A7: Factor de cobertura k del certificado: | C7: 2
A9: TABLA DE MEDICIONES Y CÁLCULO DE INCERTIDUMBRES
A10: Rango | B10: Valor Patrón | C10: Unidad | D10: Lect. 1 | E10: Lect. 2 | F10: Lect. 3 | G10: Lect. 4 | H10: Lect. 5 | I10: Promedio | J10: Resolución | K10: Error (E) | L10: u(rep) | M10: u(res) | N10: u(cert) | O10: u(espec) | P10: u_c | Q10: k | R10: U
B11: (fs) | D11: (fx1) | E11: (fx2) | F11: (fx3) | G11: (fx4) | H11: (fx5) | I11: (f̄x) | J11: (dig) | K11: (f̄x - fs) | L11: Tipo A | M11: Tipo B | N11: Tipo B | O11: Tipo B | P11: Comb. | R11: Expand.
A12: 10 Hz | B12: 10 | C12: Hz | I12: =IF(COUNT(D12:H12)>0,AVERAGE(D12:H12),"") | J12: 0.001 | K12: =IF(I12<>"",I12-B12,"") | L12: =IF(COUNT(D12:H12)>1,_xlfn.STDEV.S(D12:H12)/SQRT(COUNT(D12:H12)),0) -> 0 | M12: =J12/(2*SQRT(3)) -> 0.00028867513 | N12: =$C$6/$C$7 -> 0.0005 | O12: =($C$4/1000000*ABS(B12)+$C$5)/SQRT(3) -> 0.0058023702 | P12: =IF(I12<>"",SQRT(L12^2+M12^2+N12^2+O12^2),"") | Q12: =IF(P12<>"",2,"") | R12: =IF(P12<>"",Q12*P12,"")
A13: 100 Hz | B13: 100 | C13: Hz | I13: =IF(COUNT(D13:H13)>0,AVERAGE(D13:H13),"") | J13: 0.01 | K13: =IF(I13<>"",I13-B13,"") | L13: =IF(COUNT(D13:H13)>1,_xlfn.STDEV.S(D13:H13)/SQRT(COUNT(D13:H13)),0) -> 0 | M13: =J13/(2*SQRT(3)) -> 0.0028867513 | N13: =$C$6/$C$7 -> 0.0005 | O13: =($C$4/1000000*ABS(B13)+$C$5)/SQRT(3) -> 0.0060621778 | P13: =IF(I13<>"",SQRT(L13^2+M13^2+N13^2+O13^2),"") | Q13: =IF(P13<>"",2,"") | R13: =IF(P13<>"",Q13*P13,"")
A14: 1 kHz | B14: 1000 | C14: Hz | I14: =IF(COUNT(D14:H14)>0,AVERAGE(D14:H14),"") | J14: 0.1 | K14: =IF(I14<>"",I14-B14,"") | L14: =IF(COUNT(D14:H14)>1,_xlfn.STDEV.S(D14:H14)/SQRT(COUNT(D14:H14)),0) -> 0 | M14: =J14/(2*SQRT(3)) -> 0.028867513 | N14: =$C$6/$C$7 -> 0.0005 | O14: =($C$4/1000000*ABS(B14)+$C$5)/SQRT(3) -> 0.008660254 | P14: =IF(I14<>"",SQRT(L14^2+M14^2+N14^2+O14^2),"") | Q14: =IF(P14<>"",2,"") | R14: =IF(P14<>"",Q14*P14,"")
A15: 10 kHz | B15: 10000 | C15: Hz | I15: =IF(COUNT(D15:H15)>0,AVERAGE(D15:H15),"") | J15: 1 | K15: =IF(I15<>"",I15-B15,"") | L15: =IF(COUNT(D15:H15)>1,_xlfn.STDEV.S(D15:H15)/SQRT(COUNT(D15:H15)),0) -> 0 | M15: =J15/(2*SQRT(3)) -> 0.28867513 | N15: =$C$6/$C$7 -> 0.0005 | O15: =($C$4/1000000*ABS(B15)+$C$5)/SQRT(3) -> 0.034641016 | P15: =IF(I15<>"",SQRT(L15^2+M15^2+N15^2+O15^2),"") | Q15: =IF(P15<>"",2,"") | R15: =IF(P15<>"",Q15*P15,"")
A16: 100 kHz | B16: 100000 | C16: Hz | I16: =IF(COUNT(D16:H16)>0,AVERAGE(D16:H16),"") | J16: 10 | K16: =IF(I16<>"",I16-B16,"") | L16: =IF(COUNT(D16:H16)>1,_xlfn.STDEV.S(D16:H16)/SQRT(COUNT(D16:H16)),0) -> 0 | M16: =J16/(2*SQRT(3)) -> 2.8867513 | N16: =$C$6/$C$7 -> 0.0005 | O16: =($C$4/1000000*ABS(B16)+$C$5)/SQRT(3) -> 0.29444864 | P16: =IF(I16<>"",SQRT(L16^2+M16^2+N16^2+O16^2),"") | Q16: =IF(P16<>"",2,"") | R16: =IF(P16<>"",Q16*P16,"")
A17: 1 MHz | B17: 1000000 | C17: Hz | I17: =IF(COUNT(D17:H17)>0,AVERAGE(D17:H17),"") | J17: 100 | K17: =IF(I17<>"",I17-B17,"") | L17: =IF(COUNT(D17:H17)>1,_xlfn.STDEV.S(D17:H17)/SQRT(COUNT(D17:H17)),0) -> 0 | M17: =J17/(2*SQRT(3)) -> 28.867513 | N17: =$C$6/$C$7 -> 0.0005 | O17: =($C$4/1000000*ABS(B17)+$C$5)/SQRT(3) -> 2.8925248 | P17: =IF(I17<>"",SQRT(L17^2+M17^2+N17^2+O17^2),"") | Q17: =IF(P17<>"",2,"") | R17: =IF(P17<>"",Q17*P17,"")
A18: 10 MHz | B18: 10000000 | C18: Hz | I18: =IF(COUNT(D18:H18)>0,AVERAGE(D18:H18),"") | J18: 1000 | K18: =IF(I18<>"",I18-B18,"") | L18: =IF(COUNT(D18:H18)>1,_xlfn.STDEV.S(D18:H18)/SQRT(COUNT(D18:H18)),0) -> 0 | M18: =J18/(2*SQRT(3)) -> 288.67513 | N18: =$C$6/$C$7 -> 0.0005 | O18: =($C$4/1000000*ABS(B18)+$C$5)/SQRT(3) -> 28.873287 | P18: =IF(I18<>"",SQRT(L18^2+M18^2+N18^2+O18^2),"") | Q18: =IF(P18<>"",2,"") | R18: =IF(P18<>"",Q18*P18,"")

Sheet Welch-Satterthwaite
A1: CÁLCULO DE GRADOS EFECTIVOS DE LIBERTAD - FÓRMULA DE WELCH-SATTERTHWAITE
A2: Para determinar el factor de cobertura k exacto según GUM (ISO/IEC Guide 98-3)
A4: FÓRMULA DE WELCH-SATTERTHWAITE
A5: νeff = uc⁴ / Σ(ui⁴/νi)
A7: Donde:
A8: νeff = Grados efectivos de libertad | uc = Incertidumbre combinada | ui = Incertidumbre componente i | νi = Grados de libertad de componente i
A10: DATOS DE ENTRADA (Ingrese los valores de una medición específica)
A12: Componente | B12: Símbolo | C12: Valor u(xi) | D12: Tipo | E12: ν (g.l.) | F12: u⁴/ν | G12: n (repeticiones): | H12: 5
A13: Repetibilidad | B13: u(rep) | D13: A | E13: =H12-1 -> 4 | F13: =IF(AND(C13<>"",E13<>"",E13>0),(C13^4)/E13,0) -> 0
A14: Resolución | B14: u(res) | D14: B | E14: 200 | F14: =IF(AND(C14<>"",E14<>"",E14>0),(C14^4)/E14,0) -> 0
A15: Certificado Patrón | B15: u(cert) | D15: B | E15: 200 | F15: =IF(AND(C15<>"",E15<>"",E15>0),(C15^4)/E15,0) -> 0
A16: Especificaciones Patrón | B16: u(espec) | D16: B | E16: 200 | F16: =IF(AND(C16<>"",E16<>"",E16>0),(C16^4)/E16,0) -> 0
A17: Otros (si aplica) | B17: u(otros) | D17: B | E17: 200 | F17: =IF(AND(C17<>"",E17<>"",E17>0),(C17^4)/E17,0) -> 0
A19: RESULTADOS
A21: Suma de u⁴/ν: | B21: =SUM(F13:F17) -> 0
A22: Incertidumbre combinada uc: | B22: =SQRT(SUMSQ(C13:C17)) -> 0
A23: uc⁴: | B23: =B22^4 -> 0
A24: Grados efectivos de libertad νeff: | B24: =IF(B21>0,B23/B21,0) -> 0
A25: νeff redondeado (hacia abajo): | B25: =INT(B24) -> 0
A26: Factor de cobertura k (95.45%): | B26: =IF(B25>=1,IF(B25>=100,2,IF(B25>=50,2.01,IF(B25>=30,2.04,IF(B25>=20,2.09,IF(B25>=15,2.13,IF(B25>=10,2.23,IF(B25>=8,2.31,IF(B25>=6,2.45,IF(B25>=5,2.57,IF(B25>=4,2.78,IF(B25>=3,3.18,IF(B25>=2,4.3,12.71)))))))))))),2) -> 2
A28: TABLA DE REFERENCIA: Factor t de Student (95.45% de confianza)
A30: ν (g.l.) | B30: t (k) | D30: ν (g.l.) | E30: t (k)
A31: 1 | B31: 12.71 | D31: 25 | E31: 2.06
A32: 2 | B32: 4.3 | D32: 30 | E32: 2.04
A33: 3 | B33: 3.18 | D33: 40 | E33: 2.02
A34: 4 | B34: 2.78 | D34: 50 | E34: 2.01
A35: 5 | B35: 2.57 | D35: 60 | E35: 2
A36: 6 | B36: 2.45 | D36: 80 | E36: 1.99
A37: 7 | B37: 2.36 | D37: 100 | E37: 1.98
A38: 8 | B38: 2.31 | D38: 200 | E38: 1.97
A39: 9 | B39: 2.26 | D39: 500 | E39: 1.96
A40: 10 | B40: 2.23 | D40: 1000 | E40: 1.96
A41: 15 | B41: 2.13 | D41: ∞ | E41: 1.96
A42: 20 | B42: 2.09
A44: EJEMPLO DE USO
A46: 1. Copie los valores de incertidumbre de cualquier hoja de medición (columnas L, M, N, O)
A47: 2. Pegue cada valor en la columna C (Valor u(xi)) correspondiente
A48: 3. Verifique el número de repeticiones en H12
A49: 4. El factor k calculado aparecerá en B26
A51: NOTA IMPORTANTE:
...

Sheet Resumen Certificado
A1: RESUMEN DE RESULTADOS PARA CERTIFICADO DE CALIBRACIÓN
A3: DATOS DEL INSTRUMENTO
A4: N° Certificado: | B4: ='Datos Generales'!B5 -> 0 | C4: Fecha: | D4: ='Datos Generales'!D5 -> 0
A5: Marca IBC: | B5: ='Datos Generales'!B9 -> Arduino | C5: Modelo: | D5: ='Datos Generales'!D9 -> INA219
A6: N° Serie: | B6: ='Datos Generales'!B10 -> 0 | C6: Resolución: | D6: ='Datos Generales'!B11 -> 0
A7: Temperatura (°C): | B7: ='Datos Generales'!B21 -> 0 | C7: Humedad (%): | D7: ='Datos Generales'!D21 -> 0
A9: RESULTADOS - TENSIÓN CONTINUA (DC)
A10: Rango | B10: Valor Patrón | C10: Unidad | D10: Indicación IBC | E10: Error | F10: U (k=2) | G10: Unidad
A11: =IF('Tensión DC'!A12<>"",'Tensión DC'!A12,"") -> 2.8 | B11: =IF('Tensión DC'!B12<>"",'Tensión DC'!B12,"") -> 2.882 | C11: =IF('Tensión DC'!C12<>"",'Tensión DC'!C12,"") -> V | D11: =IF('Tensión DC'!I12<>"",'Tensión DC'!I12,"") -> 2.8522 | E11: =IF('Tensión DC'!K12<>"",'Tensión DC'!K12,"") -> -0.0298 | F11: =IF('Tensión DC'!R12<>"",'Tensión DC'!R12,"") -> 0.00071302485 | G11: =IF('Tensión DC'!C12<>"",'Tensión DC'!C12,"") -> V
A12: =IF('Tensión DC'!A13<>"",'Tensión DC'!A13,"") -> 3.3 | B12: =IF('Tensión DC'!B13<>"",'Tensión DC'!B13,"") -> 3.32 | C12: =IF('Tensión DC'!C13<>"",'Tensión DC'!C13,"") -> V | D12: =IF('Tensión DC'!I13<>"",'Tensión DC'!I13,"") -> 3.3576 | E12: =IF('Tensión DC'!K13<>"",'Tensión DC'!K13,"") -> 0.0376 | F12: =IF('Tensión DC'!R13<>"",'Tensión DC'!R13,"") -> 0.00076886905 | G12: =IF('Tensión DC'!C13<>"",'Tensión DC'!C13,"") -> V
A13: =IF('Tensión DC'!A14<>"",'Tensión DC'!A14,"") -> 3.7 | B13: =IF('Tensión DC'!B14<>"",'Tensión DC'!B14,"") -> 3.718 | C13: =IF('Tensión DC'!C14<>"",'Tensión DC'!C14,"") -> V | D13: =IF('Tensión DC'!I14<>"",'Tensión DC'!I14,"") -> 3.7614 | E13: =IF('Tensión DC'!K14<>"",'Tensión DC'!K14,"") -> 0.0434 | F13: =IF('Tensión DC'!R14<>"",'Tensión DC'!R14,"") -> 0.0057960226 | G13: =IF('Tensión DC'!C14<>"",'Tensión DC'!C14,"") -> V
A14: =IF('Tensión DC'!A15<>"",'Tensión DC'!A15,"") -> 4.2 | B14: =IF('Tensión DC'!B15<>"",'Tensión DC'!B15,"") -> 4.216 | C14: =IF('Tensión DC'!C15<>"",'Tensión DC'!C15,"") -> V | D14: =IF('Tensión DC'!I15<>"",'Tensión DC'!I15,"") -> 4.2668 | E14: =IF('Tensión DC'!K15<>"",'Tensión DC'!K15,"") -> 0.0508 | F14: =IF('Tensión DC'!R15<>"",'Tensión DC'!R15,"") -> 0.057736622 | G14: =IF('Tensión DC'!C15<>"",'Tensión DC'!C15,"") -> V
A15: =IF('Tensión DC'!A16<>"",'Tensión DC'!A16,"") -> 5 | B15: =IF('Tensión DC'!B16<>"",'Tensión DC'!B16,"") -> 5.005 | C15: =IF('Tensión DC'!C16<>"",'Tensión DC'!C16,"") -> V | D15: =IF('Tensión DC'!I16<>"",'Tensión DC'!I16,"") -> 5.0666 | E15: =IF('Tensión DC'!K16<>"",'Tensión DC'!K16,"") -> 0.0616 | F15: =IF('Tensión DC'!R16<>"",'Tensión DC'!R16,"") -> 0.57735085 | G15: =IF('Tensión DC'!C16<>"",'Tensión DC'!C16,"") -> V
A16: =IF('Tensión DC'!A17<>"",'Tensión DC'!A17,"") | B16: =IF('Tensión DC'!B17<>"",'Tensión DC'!B17,"") | C16: =IF('Tensión DC'!C17<>"",'Tensión DC'!C17,"") | D16: =IF('Tensión DC'!I17<>"",'Tensión DC'!I17,"") | E16: =IF('Tensión DC'!K17<>"",'Tensión DC'!K17,"") | F16: =IF('Tensión DC'!R17<>"",'Tensión DC'!R17,"") | G16: =IF('Tensión DC'!C17<>"",'Tensión DC'!C17,"")
A17: =IF('Tensión DC'!A18<>"",'Tensión DC'!A18,"") | B17: =IF('Tensión DC'!B18<>"",'Tensión DC'!B18,"") | C17: =IF('Tensión DC'!C18<>"",'Tensión DC'!C18,"") | D17: =IF('Tensión DC'!I18<>"",'Tensión DC'!I18,"") | E17: =IF('Tensión DC'!K18<>"",'Tensión DC'!K18,"") | F17: =IF('Tensión DC'!R18<>"",'Tensión DC'!R18,"") | G17: =IF('Tensión DC'!C18<>"",'Tensión DC'!C18,"")
A18: =IF('Tensión DC'!A19<>"",'Tensión DC'!A19,"") | B18: =IF('Tensión DC'!B19<>"",'Tensión DC'!B19,"") | C18: =IF('Tensión DC'!C19<>"",'Tensión DC'!C19,"") | D18: =IF('Tensión DC'!I19<>"",'Tensión DC'!I19,"") | E18: =IF('Tensión DC'!K19<>"",'Tensión DC'!K19,"") | F18: =IF('Tensión DC'!R19<>"",'Tensión DC'!R19,"") | G18: =IF('Tensión DC'!C19<>"",'Tensión DC'!C19,"")
A19: =IF('Tensión DC'!A20<>"",'Tensión DC'!A20,"") | B19: =IF('Tensión DC'!B20<>"",'Tensión DC'!B20,"") | C19: =IF('Tensión DC'!C20<>"",'Tensión DC'!C20,"") | D19: =IF('Tensión DC'!I20<>"",'Tensión DC'!I20,"") | E19: =IF('Tensión DC'!K20<>"",'Tensión DC'!K20,"") | F19: =IF('Tensión DC'!R20<>"",'Tensión DC'!R20,"") | G19: =IF('Tensión DC'!C20<>"",'Tensión DC'!C20,"")
A20: =IF('Tensión DC'!A21<>"",'Tensión DC'!A21,"") | B20: =IF('Tensión DC'!B21<>"",'Tensión DC'!B21,"") | C20: =IF('Tensión DC'!C21<>"",'Tensión DC'!C21,"") | D20: =IF('Tensión DC'!I21<>"",'Tensión DC'!I21,"") | E20: =IF('Tensión DC'!K21<>"",'Tensión DC'!K21,"") | F20: =IF('Tensión DC'!R21<>"",'Tensión DC'!R21,"") | G20: =IF('Tensión DC'!C21<>"",'Tensión DC'!C21,"")
A22: RESULTADOS - TENSIÓN ALTERNA (AC)
A23: Rango | B23: Valor Patrón | C23: Frecuencia | D23: Unidad | E23: Indicación | F23: Error | G23: U (k=2) | H23: Unidad
A24: =IF('Tensión AC'!A12<>"",'Tensión AC'!A12,"") | B24: =IF('Tensión AC'!B12<>"",'Tensión AC'!B12,"") | C24: =IF('Tensión AC'!C12<>"",'Tensión AC'!C12,"") | D24: =IF('Tensión AC'!D12<>"",'Tensión AC'!D12,"") -> V | E24: =IF('Tensión AC'!J12<>"",'Tensión AC'!J12,"") | F24: =IF('Tensión AC'!L12<>"",'Tensión AC'!L12,"") | G24: =IF('Tensión AC'!S12<>"",'Tensión AC'!S12,"") | H24: =IF('Tensión AC'!D12<>"",'Tensión AC'!D12,"") -> V
A25: =IF('Tensión AC'!A13<>"",'Tensión AC'!A13,"") | B25: =IF('Tensión AC'!B13<>"",'Tensión AC'!B13,"") | C25: =IF('Tensión AC'!C13<>"",'Tensión AC'!C13,"") | D25: =IF('Tensión AC'!D13<>"",'Tensión AC'!D13,"") -> V | E25: =IF('Tensión AC'!J13<>"",'Tensión AC'!J13,"") | F25: =IF('Tensión AC'!L13<>"",'Tensión AC'!L13,"") | G25: =IF('Tensión AC'!S13<>"",'Tensión AC'!S13,"") | H25: =IF('Tensión AC'!D13<>"",'Tensión AC'!D13,"") -> V
A26: =IF('Tensión AC'!A14<>"",'Tensión AC'!A14,"") | B26: =IF('Tensión AC'!B14<>"",'Tensión AC'!B14,"") | C26: =IF('Tensión AC'!C14<>"",'Tensión AC'!C14,"") | D26: =IF('Tensión AC'!D14<>"",'Tensión AC'!D14,"") -> V | E26: =IF('Tensión AC'!J14<>"",'Tensión AC'!J14,"") | F26: =IF('Tensión AC'!L14<>"",'Tensión AC'!L14,"") | G26: =IF('Tensión AC'!S14<>"",'Tensión AC'!S14,"") | H26: =IF('Tensión AC'!D14<>"",'Tensión AC'!D14,"") -> V
A27: =IF('Tensión AC'!A15<>"",'Tensión AC'!A15,"") | B27: =IF('Tensión AC'!B15<>"",'Tensión AC'!B15,"") | C27: =IF('Tensión AC'!C15<>"",'Tensión AC'!C15,"") | D27: =IF('Tensión AC'!D15<>"",'Tensión AC'!D15,"") -> V | E27: =IF('Tensión AC'!J15<>"",'Tensión AC'!J15,"") | F27: =IF('Tensión AC'!L15<>"",'Tensión AC'!L15,"") | G27: =IF('Tensión AC'!S15<>"",'Tensión AC'!S15,"") | H27: =IF('Tensión AC'!D15<>"",'Tensión AC'!D15,"") -> V
A28: =IF('Tensión AC'!A16<>"",'Tensión AC'!A16,"") | B28: =IF('Tensión AC'!B16<>"",'Tensión AC'!B16,"") | C28: =IF('Tensión AC'!C16<>"",'Tensión AC'!C16,"") | D28: =IF('Tensión AC'!D16<>"",'Tensión AC'!D16,"") | E28: =IF('Tensión AC'!J16<>"",'Tensión AC'!J16,"") | F28: =IF('Tensión AC'!L16<>"",'Tensión AC'!L16,"") | G28: =IF('Tensión AC'!S16<>"",'Tensión AC'!S16,"") | H28: =IF('Tensión AC'!D16<>"",'Tensión AC'!D16,"")
A29: =IF('Tensión AC'!A17<>"",'Tensión AC'!A17,"") | B29: =IF('Tensión AC'!B17<>"",'Tensión AC'!B17,"") | C29: =IF('Tensión AC'!C17<>"",'Tensión AC'!C17,"") | D29: =IF('Tensión AC'!D17<>"",'Tensión AC'!D17,"") | E29: =IF('Tensión AC'!J17<>"",'Tensión AC'!J17,"") | F29: =IF('Tensión AC'!L17<>"",'Tensión AC'!L17,"") | G29: =IF('Tensión AC'!S17<>"",'Tensión AC'!S17,"") | H29: =IF('Tensión AC'!D17<>"",'Tensión AC'!D17,"")
A30: =IF('Tensión AC'!A18<>"",'Tensión AC'!A18,"") | B30: =IF('Tensión AC'!B18<>"",'Tensión AC'!B18,"") | C30: =IF('Tensión AC'!C18<>"",'Tensión AC'!C18,"") | D30: =IF('Tensión AC'!D18<>"",'Tensión AC'!D18,"") | E30: =IF('Tensión AC'!J18<>"",'Tensión AC'!J18,"") | F30: =IF('Tensión AC'!L18<>"",'Tensión AC'!L18,"") | G30: =IF('Tensión AC'!S18<>"",'Tensión AC'!S18,"") | H30: =IF('Tensión AC'!D18<>"",'Tensión AC'!D18,"")
A31: =IF('Tensión AC'!A19<>"",'Tensión AC'!A19,"") | B31: =IF('Tensión AC'!B19<>"",'Tensión AC'!B19,"") | C31: =IF('Tensión AC'!C19<>"",'Tensión AC'!C19,"") | D31: =IF('Tensión AC'!D19<>"",'Tensión AC'!D19,"") | E31: =IF('Tensión AC'!J19<>"",'Tensión AC'!J19,"") | F31: =IF('Tensión AC'!L19<>"",'Tensión AC'!L19,"") | G31: =IF('Tensión AC'!S19<>"",'Tensión AC'!S19,"") | H31: =IF('Tensión AC'!D19<>"",'Tensión AC'!D19,"")
A32: =IF('Tensión AC'!A20<>"",'Tensión AC'!A20,"") | B32: =IF('Tensión AC'!B20<>"",'Tensión AC'!B20,"") | C32: =IF('Tensión AC'!C20<>"",'Tensión AC'!C20,"") | D32: =IF('Tensión AC'!D20<>"",'Tensión AC'!D20,"") | E32: =IF('Tensión AC'!J20<>"",'Tensión AC'!J20,"") | F32: =IF('Tensión AC'!L20<>"",'Tensión AC'!L20,"") | G32: =IF('Tensión AC'!S20<>"",'Tensión AC'!S20,"") | H32: =IF('Tensión AC'!D20<>"",'Tensión AC'!D20,"")
A33: =IF('Tensión AC'!A21<>"",'Tensión AC'!A21,"") | B33: =IF('Tensión AC'!B21<>"",'Tensión AC'!B21,"") | C33: =IF('Tensión AC'!C21<>"",'Tensión AC'!C21,"") | D33: =IF('Tensión AC'!D21<>"",'Tensión AC'!D21,"") | E33: =IF('Tensión AC'!J21<>"",'Tensión AC'!J21,"") | F33: =IF('Tensión AC'!L21<>"",'Tensión AC'!L21,"") | G33: =IF('Tensión AC'!S21<>"",'Tensión AC'!S21,"") | H33: =IF('Tensión AC'!D21<>"",'Tensión AC'!D21,"")
A35: RESULTADOS - CORRIENTE CONTINUA (DC)
A36: Rango | B36: Valor Patrón | C36: Unidad | D36: Indicación IBC | E36: Error | F36: U (k=2) | G36: Unidad
A37: =IF('Corriente DC'!A12<>"",'Corriente DC'!A12,"") -> 10 mA | B37: =IF('Corriente DC'!B12<>"",'Corriente DC'!B12,"") -> 10.46 | C37: =IF('Corriente DC'!C12<>"",'Corriente DC'!C12,"") -> mA | D37: =IF('Corriente DC'!I12<>"",'Corriente DC'!I12,"") -> 10.122 | E37: =IF('Corriente DC'!K12<>"",'Corriente DC'!K12,"") -> -0.338 | F37: =IF('Corriente DC'!R12<>"",'Corriente DC'!R12,"") -> 0.24636635 | G37: =IF('Corriente DC'!C12<>"",'Corriente DC'!C12,"") -> mA
A38: =IF('Corriente DC'!A13<>"",'Corriente DC'!A13,"") -> 250 mA | B38: =IF('Corriente DC'!B13<>"",'Corriente DC'!B13,"") -> 246.926 | C38: =IF('Corriente DC'!C13<>"",'Corriente DC'!C13,"") -> mA | D38: =IF('Corriente DC'!I13<>"",'Corriente DC'!I13,"") -> 247.008 | E38: =IF('Corriente DC'!K13<>"",'Corriente DC'!K13,"") -> 0.082 | F38: =IF('Corriente DC'!R13<>"",'Corriente DC'!R13,"") -> 0.53331001 | G38: =IF('Corriente DC'!C13<>"",'Corriente DC'!C13,"") -> mA
A39: =IF('Corriente DC'!A14<>"",'Corriente DC'!A14,"") -> 500 mA | B39: =IF('Corriente DC'!B14<>"",'Corriente DC'!B14,"") -> 493.951 | C39: =IF('Corriente DC'!C14<>"",'Corriente DC'!C14,"") -> mA | D39: =IF('Corriente DC'!I14<>"",'Corriente DC'!I14,"") -> 494.118 | E39: =IF('Corriente DC'!K14<>"",'Corriente DC'!K14,"") -> 0.167 | F39: =IF('Corriente DC'!R14<>"",'Corriente DC'!R14,"") -> 1.1597888 | G39: =IF('Corriente DC'!C14<>"",'Corriente DC'!C14,"") -> mA
A40: =IF('Corriente DC'!A15<>"",'Corriente DC'!A15,"") -> 1,0 A | B40: =IF('Corriente DC'!B15<>"",'Corriente DC'!B15,"") -> 989.443 | C40: =IF('Corriente DC'!C15<>"",'Corriente DC'!C15,"") -> mA | D40: =IF('Corriente DC'!I15<>"",'Corriente DC'!I15,"") -> 996.75 | E40: =IF('Corriente DC'!K15<>"",'Corriente DC'!K15,"") -> 7.307 | F40: =IF('Corriente DC'!R15<>"",'Corriente DC'!R15,"") -> 0.12831593 | G40: =IF('Corriente DC'!C15<>"",'Corriente DC'!C15,"") -> mA
A41: =IF('Corriente DC'!A16<>"",'Corriente DC'!A16,"") -> 2,0 A | B41: =IF('Corriente DC'!B16<>"",'Corriente DC'!B16,"") -> 1986.89 | C41: =IF('Corriente DC'!C16<>"",'Corriente DC'!C16,"") -> mA | D41: =IF('Corriente DC'!I16<>"",'Corriente DC'!I16,"") -> 2054.458 | E41: =IF('Corriente DC'!K16<>"",'Corriente DC'!K16,"") -> 67.568 | F41: =IF('Corriente DC'!R16<>"",'Corriente DC'!R16,"") -> 0.40818022 | G41: =IF('Corriente DC'!C16<>"",'Corriente DC'!C16,"") -> mA
A42: =IF('Corriente DC'!A17<>"",'Corriente DC'!A17,"") | B42: =IF('Corriente DC'!B17<>"",'Corriente DC'!B17,"") | C42: =IF('Corriente DC'!C17<>"",'Corriente DC'!C17,"") | D42: =IF('Corriente DC'!I17<>"",'Corriente DC'!I17,"") | E42: =IF('Corriente DC'!K17<>"",'Corriente DC'!K17,"") | F42: =IF('Corriente DC'!R17<>"",'Corriente DC'!R17,"") | G42: =IF('Corriente DC'!C17<>"",'Corriente DC'!C17,"")
A43: =IF('Corriente DC'!A18<>"",'Corriente DC'!A18,"") | B43: =IF('Corriente DC'!B18<>"",'Corriente DC'!B18,"") | C43: =IF('Corriente DC'!C18<>"",'Corriente DC'!C18,"") | D43: =IF('Corriente DC'!I18<>"",'Corriente DC'!I18,"") | E43: =IF('Corriente DC'!K18<>"",'Corriente DC'!K18,"") | F43: =IF('Corriente DC'!R18<>"",'Corriente DC'!R18,"") | G43: =IF('Corriente DC'!C18<>"",'Corriente DC'!C18,"")
A44: =IF('Corriente DC'!A19<>"",'Corriente DC'!A19,"") | B44: =IF('Corriente DC'!B19<>"",'Corriente DC'!B19,"") | C44: =IF('Corriente DC'!C19<>"",'Corriente DC'!C19,"") | D44: =IF('Corriente DC'!I19<>"",'Corriente DC'!I19,"") | E44: =IF('Corriente DC'!K19<>"",'Corriente DC'!K19,"") | F44: =IF('Corriente DC'!R19<>"",'Corriente DC'!R19,"") | G44: =IF('Corriente DC'!C19<>"",'Corriente DC'!C19,"")
...
